Workbook

Sheet Smoke Test Guidelines
A1: 📖 ข้อกำหนดและแนวทางการใช้งาน (Smoke Test Instructions & Guidelines)
A2: คำแนะนำสำหรับทีมทดสอบ เพื่อความเข้าใจวัตถุประสงค์ การเก็บหลักฐาน การสรุปผลลง Linear และปัจจัยความสำเร็จ
A4: 🎯 1. วัตถุประสงค์และปัจจัยความสำเร็จ (Key Success Factors)
A5: ทำไมต้องทำ Smoke Test ก่อนเปิด UAT? Smoke Test มีเป้าหมายเพื่อ 'ตรวจสอบความพร้อมของระบบในภาพรวม (Quick Verification)' ว่า E2E Flow หลักทำงานได้ ไม่พังทลาย ก่อนที่จะปล่อยให้ผู้ใช้งานจริง (UAT Users) เข้ามาทดสอบ โดยมี 3 ปัจจัยความสำเร็จหลัก ได้แก่: 1. มี Data Chain Tracker บันทึกรหัสกลางร่วมกัน (Centralized Data Chain): - ในระบบ HIS ข้อมูลเชื่อมโยงกันข้ามแผนก (HN -> VN -> AN -> Order ID -> Bill No.) ทุกคนในทีมต้องใช้และลงบันทึกในตาราง Header เดียวกัน เพื่อให้เห็นการส่งต่อข้อมูลแบบ End-to-End จริง 2. โฟกัสการทดสอบแบบ Quick Check / Happy Path: - เน้นตรวจสอบตามขั้นตอนแบบย่อในตาราง ไม่ต้องจมกับ Edge Cases ในรอบนี้ หากเจอ Bug ติดขัดเกิน 5 นาที ให้ทำเครื่องหมาย FAIL/BLOCKED แล้วข้ามไปข้อถัดไปทันที เพื่อคุมเวลาให้อยู่ใน 45-60 นาที 3. กำหนด Go / No-Go Decision Gate ชัดเจนก่อนเปิด UAT: - Scenarios สำคัญระดับ Critical (เช่น SC-01 คัดกรอง, SC-05 จองเตียง, SC-07 IPD Orders, SC-14 Discharge ปิดบิล) ต้อง PASS 100% หากไม่ผ่าน ห้ามเปิดรอบ UAT เด็ดขาด
A7: 📸 2. รูปแบบการเก็บผลลัพธ์และหลักฐาน (Evidence & Defect Tracking Guidelines)
A8: 1. การเก็บหลักฐานภาพถ่ายหน้าจอ (Key Milestone Screenshots): - ในรอบ Smoke Test ไม่จำเป็นต้องแคปหน้าจอทุกขั้นตอน ให้แคปเฉพาะ '4 จุดสำเร็จสำคัญ' เพื่อยืนยันความสมบูรณ์ของ E2E Flow: [1] OPD Visit Completed: หน้าจอส่ง Order OPD หรือสร้าง Admit Order สำเร็จ [2] IPD Admit & Bed Occupied: ผังเตียงที่แสดงผู้ป่วยเข้าพักใน Ward สำเร็จ [3] MAR / Dispensed: หน้า e-MAR หรือหน้ายืนยันการจ่ายยาสำเร็จ [4] Discharge & Bill Closed: ใบเสร็จรับเงินยอดสุดท้าย + สถานะจำหน่ายสำเร็จ 2. มาตรฐานการตั้งชื่อไฟล์ภาพ Bug (Defect Screenshot Naming Convention): - หากพบข้อผิดพลาด ให้แคปภาพหน้าจอและตั้งชื่อไฟล์ตามรูปแบบมาตรฐาน เพื่อให้ทีม Dev/QA สืบค้นได้ทันที: รูปแบบ: [ScenarioID]_[Role]_[ShortDescription]_[YYYYMMDD] ตัวอย่าง: SC05_BedAdmin_CannotGenerateAN_20260821.png SC09_Pharmacy_StockNotDeducted_20260821.png
A10: 📝 3. ตัวอย่างแบบฟอร์ม Dashboard สรุปผล ส่งใน Linear ก่อนเริ่ม UAT
A11: เมื่อทดสอบเสร็จเรียบร้อยแล้ว ให้คัดลอก (Copy) ข้อความตามโครงสร้างด้านล่างนี้ ไปโพสต์สรุปผลใน Linear Issue / Requirement การทดสอบ ก่อนแจ้งเปิดรอบ UAT:
A12: 📢 [Smoke Test Summary Report] - Pre-UAT Verification Sign-off 🗓 Date: 2026-08-21 | Environment: STAGING / UAT | Run ID: SM-RUN-001 👤 Tester: [ระบุชื่อผู้ทดสอบ] 📊 Overall Status: 🟢 READY FOR UAT (Pass Rate: 94.1%) • Total Scenarios: 17 Scenarios • 🟢 Passed: 16 Scenarios • 🔴 Failed: 1 Scenario (SC-15 Report PDF format alignment error - Non-critical) • 🟡 Blocked: 0 Scenarios 🔗 Primary E2E Data Chain Tracked: • HN: HN69001 | VN: VN260012 | AN: AN690088 | Bill No: INV-551 ⚠️ Open Defect / Issue Links: • [Issue-102] SC-15 Report สรุปยอดตอนเย็น จัดหน้า PDF เหลื่อม (Assignee: DevTeam) ✅ Recommendation / Sign-off: ระบบผ่านการตรวจความพร้อมหลักครบถ้วน อนุมัติเปิดให้ผู้ใช้งานทดสอบรอบ UAT ได้ตามกำหนดการ

Sheet Smoke Test Execution
A1: 🏥 Smoke Test Script & Execution Tracker
A2: การทดสอบความพร้อมแบบเร่งด่วน (Smoke Test) ครอบคลุม 17 Scenarios ครบถ้วนตาม E2E Flow OPD to IPD
A3: ⚠️ โปรดอ่านข้อกำหนด รูปแบบการเก็บหลักฐาน ปัจจัยความสำเร็จ และรูปแบบรายงาน Linear ที่ Sheet 'Smoke Test Guidelines' ก่อนเริ่มทำการทดสอบ
A4: 📌 ข้อมูลการทดสอบและสรุปผล (Test Run Information & Data Chain Tracker)
A5: Hospital Site: | B5: NUH (Naresuan University Hospital) | C5: System Version: | D5: v1.0.0 | E5: Delivery Batch (งวดส่งงาน): | F5: งวดที่ 1 | G5: Test Run ID: | H5: SM-RUN-001
A6: Test Cycle: | B6: Cycle 1 | C6: Date Executed: | D6: 2026-08-21 | E6: Environment: | F6: STAGING / UAT | G6: Tester Name: | H6: [ชื่อผู้ทดสอบ]
A7: Primary HN: | B7: HN...... | C7: Primary VN: | D7: VN...... | E7: Primary AN: | F7: AN...... | G7: Order IDs: | H7: ORD......
A8: Bill No.: | B8: INV...... | C8: Pass Count: | D8: 0 / 17 | E8: Overall Status: | F8: NOT STARTED
A9: ลำดับ (No.) | B9: ระบบ (Flow) | C9: รหัสบททดสอบ (Scenario ID) | D9: ขอบเขตและชื่อบททดสอบ (Scenario Scope & Name) | E9: ผู้ดำเนินการ (Role / Actor) | F9: ขั้นตอนทดสอบแบบย่อ (Quick Test Steps) | G9: เกณฑ์การผ่าน (Expected Pass Criteria) | H9: ผลการทดสอบ (Status) | I9: หมายเหตุ / เลข Bug (Notes / Bug ID)
A10: 1 | B10: OPD | C10: SC-01 | D10: ลงทะเบียน คัดกรอง ก่อนเข้าตรวจ OPD (ผู้ป่วย Walk-in ลงทะเบียนแล้วถูกส่งต่อไปแผนกคัดกรอง และ เข้าคิว OPD) | E10: เวชระเบียน / พยาบาลคัดกรอง / พยาบาล OPD | F10: 1. ค้นหา/สร้าง HN -> ลงทะเบียน Visit -> พิมพ์ใบนำทาง 2. พยาบาลคัดกรองดู tab 'คำขอ Walk-in' -> บันทึก Vital Sign -> เลือกแพทย์/นัด -> พิมพ์บัตรคิว 3. คิวขึ้น tab 'รอเช็คอิน' -> กด Check-in -> กดเรียกคิว -> กด 'พร้อมตรวจ' | G10: สถานะผู้ป่วยเปลี่ยนเป็น 'กำลังดำเนินการ' และคิวแสดงหน้าห้องตรวจ | H10: Not Run
A11: 2 | B11: OPD | C11: SC-02 [A] | D11: แพทย์ตรวจ + วินิจฉัย + สั่ง Order (Lab/X-ray/ยา) (พยาบาลหน้าห้องตรวจกดเรียกคิว ตรวจผู้ป่วย OPD พร้อมกัน เพื่อเข้าห้องตรวจ แล้วสั่ง Order) | E11: แพทย์ OPD / พยาบาลหน้าห้องตรวจ | F11: 1. พยาบาลกดเรียกคิวเข้าห้องตรวจ 2. แพทย์เปิด EMR เปลี่ยนสถานะ 'พร้อม' -> บันทึก Diagnosis (ICD-10) 3. สั่ง Order ครบ 3 ชนิด (Lab + X-ray + ยา) ลงตะกร้า -> กด 'ส่งคำสั่ง' (Submit Order) | G11: ส่ง Order ทั้งหมดสำเร็จในครั้งเดียว และสถานะผู้ป่วยเปลี่ยนเป็น 'พักการตรวจ' | H11: Not Run
A12: 3 | B12: OPD | C12: SC-03 | D12: ส่ง Lab/X-ray -> รับผล -> แพทย์อ่านผลต่อ (ระบบส่ง Order ไปห้อง Lab/X-ray และประมวลผล Lab/X-ray พร้อมแพทย์อ่านผลกลับเข้าตรวจต่อ) | E12: จนท. Lab / แพทย์ OPD | F12: 1. จนท. Lab เช็คอินรายการ -> เก็บตัวอย่าง (Container) -> ยืนยัน -> ลงผล Lab -> กด Final Report 2. แพทย์เปิด EMR ดูผล -> เปลี่ยนสถานะ 'พร้อม' -> สั่งยาเพิ่ม/นัดหมาย/ออกใบรับรองแพทย์ -> กด 'ตรวจเสร็จ' | G12: ผล Lab ออกสมบูรณ์ และแพทย์เปลี่ยนสถานะผู้ป่วยเป็น 'ตรวจเสร็จ' | H12: Not Run
A13: 4 | B13: OPD | C13: SC-04 | D13: เภสัชกรรม (สร้างใบยา) -> ชำระเงิน -> เภสัชกรรม จ่ายยา -> การเงินปิด Visit (เภสัชกรสร้างใบยาส่งต่อการเงินชำระเงินแล้วเภสัชกรจ่ายยาปิด Visit ให้ผู้ป่วย OPD) | E13: เภสัชกร OPD / การเงิน | F13: 1. เภสัชกรตรวจใบสั่งยา -> กด 'สร้างใบยา' -> กด 'ยืนยันใบยา' (ตัด Stock) 2. การเงินออกใบแจ้งหนี้ -> รับชำระเงิน -> พิมพ์ใบเสร็จ -> กด 'เสร็จสิ้น' 3. เภสัชกรเห็นสถานะ 'ชำระเงินแล้ว' -> พิมพ์ฉลากยา/จัดยา -> กด 'จ่ายยา' + เรียกคิว | G13: ตัด Stock ยาสำเร็จ ออกใบเสร็จเรียบร้อย และปิด Visit OPD สมบูรณ์ | H13: Not Run
A14: 5 | B14: IPD | C14: SC-02 [B] | D14: แพทย์วินิจฉัยแล้วสั่ง Admit โดยไม่มี Order (แพทย์วินิจฉัยแล้วสั่ง Admit ผู้ป่วย OPD เข้า IPD ทันทีโดยไม่สั่ง Order) | E14: แพทย์ OPD / พยาบาล | F14: 1. พยาบาลเรียกคิว -> แพทย์เปิด EMR เปลี่ยนสถานะ 'พร้อม' -> ลงวินิจฉัย OPD Note 2. แพทย์ประเมิน 'ต้อง Admit' -> กดปุ่ม 'สร้าง Admit Order' จาก EMR -> กรอกฟอร์ม -> Save | G14: สถานะผู้ป่วยเปลี่ยนเป็น 'รอ Admit' และคำขอส่งไปศูนย์จัดการเตียง | H14: Not Run
A15: 6 | B15: IPD | C15: SC-05 | D15: จองเตียง -> สร้าง AN (ต่อเนื่องจาก Scenario 2 [B]) (จนท.เตียงจองเตียงและสร้าง AN ให้ผู้ป่วย Admit) | E15: จนท. ศูนย์จัดการเตียง | F15: 1. เข้าเมนู ศูนย์จัดการเตียง -> tab 'คำขอ Admit' -> ค้นหาผู้ป่วย -> กด 'จองเตียง' 2. เลือกวอร์ด/ประเภทเตียง/เตียง จากผังเตียง -> กดบันทึก 3. กลับ tab 'คำขอ Admit' -> กดปุ่ม 'สร้าง AN' | G15: ระบบ Generate AN สำเร็จ ข้อมูลย้ายไปแสดงใน tab 'AN' | H15: Not Run
A16: 7 | B16: IPD | C16: SC-06 | D16: ผู้ป่วยใน -> รายการเตียง หอผู้ป่วยใน (พยาบาล Ward เปิดรายการเตียงหอผู้ป่วยในและบันทึกเวลาผู้ป่วยมาถึงวอร์ด) | E16: พยาบาล Ward | F16: 1. เข้าเมนู ผู้ป่วยใน -> รายการเตียง -> เลือก Ward -> กด ส่ง 2. ไปที่ tab 'เตียงทั้งหมด' -> เลือกผู้ป่วย -> กด 3 จุด -> เลือก 'บันทึกมาถึงวอร์ด' -> บันทึกเวลา | G16: บันทึกเวลาผู้ป่วยมาถึงวอร์ดสำเร็จ ผู้ป่วยแสดงสถานะพร้อมรับการดูแลบน Ward | H16: Not Run
A17: 8 | B17: IPD | C17: SC-07 | D17: แพทย์ตรวจ + วินิจฉัย + สั่ง Order (Lab/X-ray/ยา) (แพทย์ Round ตรวจและสั่ง Order ยา/Lab/X-ray แบบ ONE DAY และ CONTINUE ให้ผู้ป่วย IPD) | E17: แพทย์ IPD | F17: 1. เปิด EMR IPD (ค้นด้วย AN) -> เข้าเมนู 'IPD Summary' -> บันทึก Progress Note 2. เข้า tab 'Physician Order' -> สั่งออเดอร์ทั้ง 'One Day Order' และ 'Continue Order' 3. กด บันทึก -> กดปุ่ม 'Sign All' | G17: Order แสดงใน tab IPD Summary แยกกลุ่ม One Day / Continue ชัดเจน Status = 'รอรับ' | H17: Not Run
A18: 9 | B18: IPD | C18: SC-08 | D18: พยาบาลตรวจสอบ Order ยา และ Confirm รายการยา (พยาบาลตรวจสอบและ Confirm รายการยาผู้ป่วย IPD แพทย์สั่ง Order ทั้งแบบ ONE DAY และ CONTINUE) | E18: พยาบาล Ward | F18: 1. เข้าเมนู ผู้ป่วยใน -> รายการเตียง -> เลือก Ward -> เปิดหน้า 'Patient IPD Summary' 2. ตรวจสอบคอลัมน์ 'ORDER FOR ONE DAY' และ 'NEW ORDER FOR CONTINUE' 3. ตรวจสอบชื่อยา/ขนาด/วิธีใช้ -> กดปุ่ม 'รับออเดอร์' ทุกรายการ | G18: สถานะ Order เปลี่ยนเป็นรับออเดอร์แล้ว และรายการถูกส่งไปห้องยา IPD | H18: Not Run
A19: 10 | B19: IPD | C19: SC-09 | D19: เภสัชกรรมจ่ายยา IPD [ONE DAY] (สร้างใบยา) -> ชำระเงิน -> เภสัชกรรม จ่ายยา -> พยาบาล Ward (เภสัชกรจ่ายยาผู้ป่วย IPD พร้อมกัน X ราย แยกตามประเภท Order ONE DAY และต้องชำระเงิน) | E19: เภสัชกร IPD / การเงิน / พยาบาล Ward | F19: 1. เภสัชกรเข้า tab 'Order รอยืนยัน' -> ตรวจสอบยา One Day -> กด 'สร้างใบยา' (พิมพ์ฉลาก auto) -> ยืนยันใบยา 2. การเงินออกใบแจ้งหนี้ -> รับชำระเงิน 3. เภสัชกรเห็นสถานะ 'ชำระเงินแล้ว' -> จัดยา -> กด 'จ่ายยา' | G19: รายการยา One Day วิ่งไปแสดงบน e-MAR ของพยาบาล Ward พร้อมจ่ายยา | H19: Not Run
A20: 11 | B20: IPD | C20: SC-10 | D20: เภสัชกรรมจ่ายยา IPD [CONTINUE] (สร้างใบยา) -> เภสัชกรรม จ่ายยา -> พยาบาล Ward (เภสัชกรจ่ายยาผู้ป่วย IPD พร้อมกัน X ราย แยกตามประเภท CONTINUE โดยไม่รอการชำระเงิน) | E20: เภสัชกร IPD / พยาบาล Ward | F20: 1. เภสัชกรเข้าเมนู 'รับ Continue Order ประจำวัน' -> เลือก Ward -> กด ค้นหา 2. กดปุ่ม 'Generate ที่เลือก' -> ระบบสร้างใบยา Continue 3. พิมพ์ฉลากยา -> กด 'จ่ายยา' (ไม่ต้องรอชำระเงิน) | G20: รายการยา Continue ประจำวันถูก Generate และแสดงบน e-MAR ของ Ward ทันที | H20: Not Run
A21: 12 | B21: IPD | C21: SC-11 | D21: จนท. Lab check-in + ลงผล + แพทย์อ่านผล (จนท. Lab ดำเนินการตรวจและบันทึกผลผู้ป่วย IPD ตามประเภท Order ONE DAY) | E21: จนท. Lab / แพทย์ IPD | F21: 1. จนท. Lab เข้า รายการแล็บ -> tab 'รอเช็คอิน' -> กด เช็คอิน -> เลือกประเภทตัวอย่าง -> กด เก็บแล้ว (Container) -> กด รับแล้ว 2. ลงผล Lab -> บันทึกร่าง -> กด Final Report 3. แพทย์เปิด Patient Profile IPD -> เมนู Lab result เพื่อดูผล | G21: สถานะ Lab Task = 'เสร็จสิ้น' (Result completed) และแพทย์เห็นผลในระบบ | H21: Not Run
... A26: 17 | B26: OPD / IPD | C26: SC-16 | D26: จนท. Coder เข้าเมนู เบิกจ่าย เพื่อลงรหัสโรค (เจ้าหน้าที่แผนก Coder เข้ามาลงรหัสโรคของผู้ป่วย) | E26: จนท. Coder | F26: 1. เข้าเมนู เบิกจ่าย -> OPD/IPD -> รายการรอรหัสโรค -> เลือกผู้ป่วยสถานะ 'รอลงรหัส' 2. ไปที่ Patient Profile -> เลือก Diagnosis + Procedure -> กด บันทึก 3. กดปุ่ม '>' เพื่อลงรหัสคนถัดไป | G26: สถานะผู้ป่วยเปลี่ยนเป็น 'ลงรหัสแล้ว' และย้ายไปแสดงใน tab ลงรหัสแล้ว | H26: Not Run

Sheet OPD to IPD (Simple flow)
A1: Flow | B1: Scenario No. | C1: Scenario Scope | D1: Scenario Name | E1: Business Flow (User Journey)
A2: OPD | B2: Scenario 1: | C2: ลงทะเบียน คัดกรอง ก่อนเข้าตรวจ OPD | D2: ผู้ป่วย Walk-in ลงทะเบียนแล้วถูกส่งต่อไปแผนกคัดกรอง และ เข้าคิว OPD | E2: [1] ค้นหา/สร้าง HN
C3: ลงทะเบียน คัดกรอง ก่อนเข้าตรวจ OPD | D3: ผู้ป่วย Walk-in ลงทะเบียนแล้วถูกส่งต่อไปแผนกคัดกรอง และ เข้าคิว OPD | E3: [2] ลงทะเบียน Visit (เลือกสิทธิ + คลินิกปลายทาง) + พิมพ์ใบนำทาง
C4: ลงทะเบียน คัดกรอง ก่อนเข้าตรวจ OPD | D4: ผู้ป่วย Walk-in ลงทะเบียนแล้วถูกส่งต่อไปแผนกคัดกรอง และ เข้าคิว OPD | E4: [3] ระบบ Generate Visit No. → แสดงรายการที่ Tab "คำขอ Walk-in"
C5: ลงทะเบียน คัดกรอง ก่อนเข้าตรวจ OPD | D5: ผู้ป่วย Walk-in ลงทะเบียนแล้วถูกส่งต่อไปแผนกคัดกรอง และ เข้าคิว OPD | E5: [4] พยาบาลคัดกรองกด Refresh ดูรายการ Tab คำขอ Walk-in
C6: ลงทะเบียน คัดกรอง ก่อนเข้าตรวจ OPD | D6: ผู้ป่วย Walk-in ลงทะเบียนแล้วถูกส่งต่อไปแผนกคัดกรอง และ เข้าคิว OPD | E6: [5] พยาบาลคัดกรองบันทึกเอกสารคัดกรอง + สัญญาณชีพ
C7: ลงทะเบียน คัดกรอง ก่อนเข้าตรวจ OPD | D7: ผู้ป่วย Walk-in ลงทะเบียนแล้วถูกส่งต่อไปแผนกคัดกรอง และ เข้าคิว OPD | E7: [6] พยาบาลคัดกรองลงตารางแพทย์ (เลือกแพทย์+เวลานัด) → บันทึก → Print บัตรคิว
C8: ลงทะเบียน คัดกรอง ก่อนเข้าตรวจ OPD | D8: ผู้ป่วย Walk-in ลงทะเบียนแล้วถูกส่งต่อไปแผนกคัดกรอง และ เข้าคิว OPD | E8: [7] ระบบส่งต่อเข้าคิวแผนก → แสดงที่ Tab "ทั้งหมด" และ Tab "รอเช็คอิน"
C9: ลงทะเบียน คัดกรอง ก่อนเข้าตรวจ OPD | D9: ผู้ป่วย Walk-in ลงทะเบียนแล้วถูกส่งต่อไปแผนกคัดกรอง และ เข้าคิว OPD | E9: [8] พยาบาล Check-in คนไข้ → เปลี่ยนสถานะเป็น "เช็คอิน" + กดบัตรคิวที่ Tab เช็คอิน
C10: ลงทะเบียน คัดกรอง ก่อนเข้าตรวจ OPD | D10: ผู้ป่วย Walk-in ลงทะเบียนแล้วถูกส่งต่อไปแผนกคัดกรอง และ เข้าคิว OPD | E10: [9] พยาบาลกดเรียกคิวที่ Tab เช็คอิน → กดปุ่ม "พร้อมตรวจ" สถานะผู้ป่วย = กำลังดำเนินการ
C11: ลงทะเบียน คัดกรอง ก่อนเข้าตรวจ OPD | D11: ผู้ป่วย Walk-in ลงทะเบียนแล้วถูกส่งต่อไปแผนกคัดกรอง และ เข้าคิว OPD | E11: [10] พยาบาลหน้าห้องตรวจกดเรียกคิว
A13: OPD | B13: Scenario 2 [A]: | C13: แพทย์ตรวจ + วินิจฉัย + สั่ง Order (Lab/X-ray/ยา) | D13: พยาบาลหน้าห้องตรวจกดเรียกคิว ตรวจผู้ป่วย OPD พร้อมกัน เพื่อเขาห้องตรวจ แล้วสั่ง Order | E13: [1] พยาบาลหน้าห้องตรวจกดเรียกคิว (รับต่อจาก SC1 step 10)
C14: แพทย์ตรวจ + วินิจฉัย + สั่ง Order (Lab/X-ray/ยา) | D14: พยาบาลหน้าห้องตรวจกดเรียกคิว ตรวจผู้ป่วย OPD พร้อมกัน เพื่อเขาห้องตรวจ แล้วสั่ง Order | E14: [2] แพทย์เปิดเวชระเบียน (EMR) ดูประวัติ + Vital Sign จากคัดกรอง + เปลี่ยนสถานะผู้ป่วย = "พร้อม"
C15: แพทย์ตรวจ + วินิจฉัย + สั่ง Order (Lab/X-ray/ยา) | D15: พยาบาลหน้าห้องตรวจกดเรียกคิว ตรวจผู้ป่วย OPD พร้อมกัน เพื่อเขาห้องตรวจ แล้วสั่ง Order | E15: [3] แพทย์บันทึกวินิจฉัย (Diagnosis/ICD-10) ด้วย Template OPD Note
C16: แพทย์ตรวจ + วินิจฉัย + สั่ง Order (Lab/X-ray/ยา) | D16: พยาบาลหน้าห้องตรวจกดเรียกคิว ตรวจผู้ป่วย OPD พร้อมกัน เพื่อเขาห้องตรวจ แล้วสั่ง Order | E16: [4] แพทย์สั่ง Order (แยก 3 เส้นทางที่อาจเกิดพร้อมกันในเคสเดียว):
C17: แพทย์ตรวจ + วินิจฉัย + สั่ง Order (Lab/X-ray/ยา) | D17: พยาบาลหน้าห้องตรวจกดเรียกคิว ตรวจผู้ป่วย OPD พร้อมกัน เพื่อเขาห้องตรวจ แล้วสั่ง Order | E17: → [4a] ค้นหา Item Lab → เลือก Item → เพิ่มลงตะกร้า
C18: แพทย์ตรวจ + วินิจฉัย + สั่ง Order (Lab/X-ray/ยา) | D18: พยาบาลหน้าห้องตรวจกดเรียกคิว ตรวจผู้ป่วย OPD พร้อมกัน เพื่อเขาห้องตรวจ แล้วสั่ง Order | E18: → [4b] ค้นหา Item X-ray → เลือก Item → เพิ่มลงตะกร้า
C19: แพทย์ตรวจ + วินิจฉัย + สั่ง Order (Lab/X-ray/ยา) | D19: พยาบาลหน้าห้องตรวจกดเรียกคิว ตรวจผู้ป่วย OPD พร้อมกัน เพื่อเขาห้องตรวจ แล้วสั่ง Order | E19: → [4c] ค้นหา Item ยา → เลือก Item → เพิ่มลงตะกร้า
C20: แพทย์ตรวจ + วินิจฉัย + สั่ง Order (Lab/X-ray/ยา) | D20: พยาบาลหน้าห้องตรวจกดเรียกคิว ตรวจผู้ป่วย OPD พร้อมกัน เพื่อเขาห้องตรวจ แล้วสั่ง Order | E20: [5] กดปุ่ม "ส่งคำสั่ง" (Submit Order ทั้งตะกร้าพร้อมกัน)
C21: แพทย์ตรวจ + วินิจฉัย + สั่ง Order (Lab/X-ray/ยา) | D21: พยาบาลหน้าห้องตรวจกดเรียกคิว ตรวจผู้ป่วย OPD พร้อมกัน เพื่อเขาห้องตรวจ แล้วสั่ง Order | E21: [6] เปลี่ยนสถานะผู้ป่วย = "พักการตรวจ"
A23: OPD | B23: Scenario 3: | C23: ส่ง Lab/X-ray → รับผล → แพทย์อ่านผลต่อ | D23: ระบบส่ง Order ไปห้อง Lab/X-ray และประมวลผล Lab/X-ray พร้อมแพทย์อ่านผลกลับเข้าตรวจต่อ | E23: [1] ระบบส่ง Order ไปคิว Lab/X-ray (auto, รับต่อจาก SC2 step 5)
C24: ส่ง Lab/X-ray → รับผล → แพทย์อ่านผลต่อ | D24: ระบบส่ง Order ไปห้อง Lab/X-ray และประมวลผล Lab/X-ray พร้อมแพทย์อ่านผลกลับเข้าตรวจต่อ | E24: [2] จนท. Lab เปิดดูรายการ Order ที่หน้า รายการงานแล็บ tab รอเช็คอิน
C25: ส่ง Lab/X-ray → รับผล → แพทย์อ่านผลต่อ | D25: ระบบส่ง Order ไปห้อง Lab/X-ray และประมวลผล Lab/X-ray พร้อมแพทย์อ่านผลกลับเข้าตรวจต่อ | E25: [3] จนท.กดเลือกรายการ Lab ที่หน้า รายละเอียด Lab Task → กดปุ่ม เช็คอิน → ยืนยัน (auto print บัตรคิว) ที่ session รายละเอียด Lab Task
C26: ส่ง Lab/X-ray → รับผล → แพทย์อ่านผลต่อ | D26: ระบบส่ง Order ไปห้อง Lab/X-ray และประมวลผล Lab/X-ray พร้อมแพทย์อ่านผลกลับเข้าตรวจต่อ | E26: [4] จนท. กดปุ่ม เก็บแล้ว ที่ session รายละเอียด Lab Task
C27: ส่ง Lab/X-ray → รับผล → แพทย์อ่านผลต่อ | D27: ระบบส่ง Order ไปห้อง Lab/X-ray และประมวลผล Lab/X-ray พร้อมแพทย์อ่านผลกลับเข้าตรวจต่อ | E27: [5] จนท. เก็บแล้ว ที่ session Container
C28: ส่ง Lab/X-ray → รับผล → แพทย์อ่านผลต่อ | D28: ระบบส่ง Order ไปห้อง Lab/X-ray และประมวลผล Lab/X-ray พร้อมแพทย์อ่านผลกลับเข้าตรวจต่อ | E28: [6] จนท. ยืนยัน ที่ session Container
C29: ส่ง Lab/X-ray → รับผล → แพทย์อ่านผลต่อ | D29: ระบบส่ง Order ไปห้อง Lab/X-ray และประมวลผล Lab/X-ray พร้อมแพทย์อ่านผลกลับเข้าตรวจต่อ | E29: [7] จนท. ลงผล Lab ที่ ลงผล Lab → กดปุ่ม บันทึกร่าง → กดปุ่ม Final Report
C30: ส่ง Lab/X-ray → รับผล → แพทย์อ่านผลต่อ | D30: ระบบส่ง Order ไปห้อง Lab/X-ray และประมวลผล Lab/X-ray พร้อมแพทย์อ่านผลกลับเข้าตรวจต่อ | E30: [8] แพทย์อ่านผล → เปลี่ยนสถานะ พร้อม :
C31: ส่ง Lab/X-ray → รับผล → แพทย์อ่านผลต่อ | D31: ระบบส่ง Order ไปห้อง Lab/X-ray และประมวลผล Lab/X-ray พร้อมแพทย์อ่านผลกลับเข้าตรวจต่อ | E31: → [8a] วินิจฉัยสรุป + สั่งยา
C32: ส่ง Lab/X-ray → รับผล → แพทย์อ่านผลต่อ | D32: ระบบส่ง Order ไปห้อง Lab/X-ray และประมวลผล Lab/X-ray พร้อมแพทย์อ่านผลกลับเข้าตรวจต่อ | E32: → [8b] สั่ง Order เพิ่ม
C33: ส่ง Lab/X-ray → รับผล → แพทย์อ่านผลต่อ | D33: ระบบส่ง Order ไปห้อง Lab/X-ray และประมวลผล Lab/X-ray พร้อมแพทย์อ่านผลกลับเข้าตรวจต่อ | E33: [9] แพทย์ สร้างนัดหมาย
C34: ส่ง Lab/X-ray → รับผล → แพทย์อ่านผลต่อ | D34: ระบบส่ง Order ไปห้อง Lab/X-ray และประมวลผล Lab/X-ray พร้อมแพทย์อ่านผลกลับเข้าตรวจต่อ | E34: [10] แพทย์ออกใบรับรองแพทย์
C35: ส่ง Lab/X-ray → รับผล → แพทย์อ่านผลต่อ | D35: ระบบส่ง Order ไปห้อง Lab/X-ray และประมวลผล Lab/X-ray พร้อมแพทย์อ่านผลกลับเข้าตรวจต่อ | E35: [11] แพทย์เปลี่ยนสถานะผู้ป่วย = "ตรวจเสร็จ"
A37: OPD | B37: Scenario 4: | C37: เภสัชกรรม (สร้างใบยา) → ชำระเงิน → เภสัชกรรม จ่ายยา → การเงินปิด Visit | D37: เภสัชกรสร้างใบยาส่งต่อการเงินชำระเงินแล้วเภสัชกรจ่ายยาปิด Visit ให้ผู้ป่วย OPD | E37: [1] เภสัชกรรม: เปิดดูรายการใบสั่งยารอสร้างใบยา (จาก SC2/SC3 Order)
C38: เภสัชกรรม (สร้างใบยา) → ชำระเงิน → เภสัชกรรม จ่ายยา → การเงินปิด Visit | D38: เภสัชกรสร้างใบยาส่งต่อการเงินชำระเงินแล้วเภสัชกรจ่ายยาปิด Visit ให้ผู้ป่วย OPD | E38: [2] เภสัชกรรม: สร้างใบยา (ตรวจสอบรายการยา + Drug Interaction/Allergy check)
C39: เภสัชกรรม (สร้างใบยา) → ชำระเงิน → เภสัชกรรม จ่ายยา → การเงินปิด Visit | D39: เภสัชกรสร้างใบยาส่งต่อการเงินชำระเงินแล้วเภสัชกรจ่ายยาปิด Visit ให้ผู้ป่วย OPD | E39: [3] เภสัชกรรม: ยืนยันใบยา → ส่งไปแผนกการเงิน และ ระบบตัด Stock ยา (hiventory)
C40: เภสัชกรรม (สร้างใบยา) → ชำระเงิน → เภสัชกรรม จ่ายยา → การเงินปิด Visit | D40: เภสัชกรสร้างใบยาส่งต่อการเงินชำระเงินแล้วเภสัชกรจ่ายยาปิด Visit ให้ผู้ป่วย OPD | E40: [4] การเงิน: เปิดรายการรอชำระ charge-items
C41: เภสัชกรรม (สร้างใบยา) → ชำระเงิน → เภสัชกรรม จ่ายยา → การเงินปิด Visit | D41: เภสัชกรสร้างใบยาส่งต่อการเงินชำระเงินแล้วเภสัชกรจ่ายยาปิด Visit ให้ผู้ป่วย OPD | E41: [5] การเงิน: สรุปค่าใช้จ่าย สร้างใบแจ้งหนี้ → พิมพ์ใบแจ้งหนี้
C42: เภสัชกรรม (สร้างใบยา) → ชำระเงิน → เภสัชกรรม จ่ายยา → การเงินปิด Visit | D42: เภสัชกรสร้างใบยาส่งต่อการเงินชำระเงินแล้วเภสัชกรจ่ายยาปิด Visit ให้ผู้ป่วย OPD | E42: [6] การเงิน: เรียกคิว → กดปุ่ม เสร็จสิ้น
C43: เภสัชกรรม (สร้างใบยา) → ชำระเงิน → เภสัชกรรม จ่ายยา → การเงินปิด Visit | D43: เภสัชกรสร้างใบยาส่งต่อการเงินชำระเงินแล้วเภสัชกรจ่ายยาปิด Visit ให้ผู้ป่วย OPD | E43: [7] เภสัชกรรม: เห็นสถานะ "ชำระเงินแล้ว" → ทำการจัดยา (auto print ใบยารายการยา)
...

Sheet Process Improvement Plan
A1: Process Improvement Plan
A3: หมวด | B3: ข้อ | C3: หัวข้อ / รายละเอียด | D3: กระทบการทำงานกับใคร | E3: ผู้ร่วมปรับปรุง | F3: Priority | G3: Status | H3: Target | I3: Target date
A4: 1. Development | B4: 1.1 | C4: วางเป้างาน develop ให้เสร็จภายในวันพุธหรือพฤหัส เพื่อให้มีเวลาทดสอบเพียงพอ หากมีแนวโน้มไม่ทัน ให้พิจารณาปรับ scope ร่วมกันล่วงหน้า | D4: กระทบ QA เพราะเวลาทดสอบจะหดหายไปตามงานที่ส่งช้า และกระทบ PO กับ BA ที่ต้องตัดสินใจเรื่อง cut scope โดยมีเวลาพิจารณาจำกัด | E4: • Dev ช่วยดูแลให้งานเสร็จตามเป้า • Lead Team กับ BA ร่วมพิจารณาการปรับ scope เมื่อเห็นแนวโน้ม | F4: High | G4: Not started | H4: D4
A5: 2. Requirement & Grooming | B5: 2.1 | C5: ดูแลให้ Requirement และ AC เป็นปัจจุบันก่อน QA เริ่มเตรียมเทสเคส เพื่อให้ทุกฝ่ายเข้าใจขอบเขตงานตรงกัน | D5: กระทบ QA ที่อาจเตรียมเทสเคสจากข้อมูลที่ไม่เป็นปัจจุบัน และกระทบ Dev ที่อาจพัฒนาคนละทิศทางกับสิ่งที่ตกลงกันไว้ | E5: • BA ช่วยอัปเดต Requirement และ AC ให้เรียบร้อยก่อนงานเข้า sprint | F5: High | G5: Not started | H5: D4
A6: 2. Requirement & Grooming | B6: 2.2 | C6: เชิญ QA ร่วม grooming และร่วมประเมิน point เพื่อให้แผนงานสะท้อนกำลังของทีมครบทุกฝ่าย | D6: กระทบการประเมินกำลังงานของทั้งทีม เนื่องจาก point ที่ไม่รวมงานฝั่ง QA ทำให้แผนการ sprint คลาดเคลื่อนจากความเป็นจริง | E6: • Lead Team ช่วยเชิญ QA เข้าวง grooming • QA ร่วมให้ point งานฝั่งทดสอบ | F6: Medium | G6: Not started | H6: D4
A7: 3. QA Process | B7: 3.1 | C7: run OPD to IPD หนึ่งรอบช่วงท้ายของทุก Cycle เพื่อตรวจว่า flow หลักยังใช้งานได้ตามเดิม | D7: กระทบ QA ที่มีงาน run เพิ่มทุกท้าย Cycle และกระทบ Dev ที่อาจต้องกลับมาแก้งานช่วงท้ายรอบ | E7: • QA ช่วย run E2E ช่วงท้ายของทุก Cycle • QA แจ้งผลให้ทีมทราบ | F7: High | G7: Not started | H7: D4
A8: 3. QA Process | B8: 3.2 | C8: run OPD to IPD ก่อนส่งงาน UAT หรือ Training ทุกครั้ง เพื่อให้มั่นใจว่างานพร้อมส่งถึงมือผู้ใช้งาน | D8: กระทบผู้ใช้งานและลูกค้าที่อาจพบปัญหาหน้างาน และกระทบ PO ที่ต้องดูแลความเชื่อมั่นของทีม | E8: • QA ช่วย run ก่อนส่งงานทุกครั้ง • Lead Team ร่วมยืนยันกำหนด release เมื่อผลทดสอบเรียบร้อย | F8: High | G8: Not started | H8: D4
A9: 3. QA Process | B9: 3.3 | C9: เก็บสถิติจำนวน bug ที่พบหลังส่งงานในแต่ละรอบ UAT และ Training เพื่อใช้ดูแนวโน้มคุณภาพและหาจุดที่ควรปรับปรุง | D9: เป็นข้อมูลกลางที่ทั้งทีมใช้อ้างอิงเพื่อดูแนวโน้มคุณภาพ และช่วยให้ผู้บริหารเห็นความคืบหน้าของการปรับปรุง | E9: • QA Lead ช่วยรวบรวมสถิติและสรุปให้ทีมเห็นภาพรวมทุกรอบ | F9: Medium | G9: Not started | H9: D4
A10: 4. Team & Ownership | B10: 4.1 | C10: ระบุชื่อผู้รับผิดชอบฝั่ง BA / Dev / QA ไว้ในการ์ด เพื่อให้ติดตามและประสานงานกันได้สะดวก | D10: กระทบทั้งทีมเมื่อติดตามงาน เพราะไม่ทราบว่าควรสอบถามหรือประสานงานกับใคร | E10: • ทุกคนช่วยระบุชื่อตนเองในการ์ด • Scrum Master ช่วยทบทวนก่อนปิด sprint | F10: Medium | G10: Not started | H10: D4

Sheet Bug Log
A1: Bug Log – บันทึก bug ที่พบหลังส่งงาน
A2: กรอกหนึ่งแถวต่อหนึ่ง bug ที่พบ หน้า Bug Dashboard จะสรุปให้อัตโนมัติ
A4: Bug ID | B4: รอบที่ส่ง | C4: ประเภทการส่ง | D4: วันที่พบ | E4: Module / ฟังก์ชัน | F4: หัวข้ออาการ | G4: Severity | H4: สาเหตุที่หลุด | I4: ผู้พบ | J4: ผู้แก้ไข | K4: สถานะ | L4: หมายเหตุ
A5: BUG-001 | B5: D4-1 | C5: UAT | D5: 46255 | E5: OPD – ลงทะเบียน | F5: กดบันทึกซ้ำแล้วเกิดข้อมูลผู้ป่วยซ้ำ 2 รายการ | G5: High | H5: Requirement / AC ไม่ครอบคลุม | I5: ผู้ใช้งาน | J5: Dev A | K5: Fixed | L5: เดิมระบุ: Requirement ไม่ครอบคลุมเคส double-click
A6: BUG-002 | B6: D4-1 | C6: Training | D6: 46255 | E6: IPD – Admit | F6: หน้าจอ Admit ไม่แสดงเตียงว่างบางหอผู้ป่วย | G6: Medium | H6: ข้อมูลทดสอบไม่ครบ | I6: QA | J6: Dev B | K6: In progress

Sheet Bug Dashboard
A1: Bug Dashboard – สรุปแนวโน้มคุณภาพ
A2: ทุกตัวเลขคำนวณอัตโนมัติจากหน้า Bug Log — เพิ่มรอบใหม่ได้ที่คอลัมน์ A
A4: 1. สรุปรายรอบส่งงาน
A5: รอบที่ส่ง | B5: Critical | C5: High | D5: Medium | E5: Low | F5: รวม bug | G5: แก้แล้ว | H5: คงเหลือ
A6: D4-1 | B6: =COUNTIFS('Bug Log'!$B$5:$B$200,$A6,'Bug Log'!$G$5:$G$200,B$5) | C6: =COUNTIFS('Bug Log'!$B$5:$B$200,$A6,'Bug Log'!$G$5:$G$200,C$5) | D6: =COUNTIFS('Bug Log'!$B$5:$B$200,$A6,'Bug Log'!$G$5:$G$200,D$5) | E6: =COUNTIFS('Bug Log'!$B$5:$B$200,$A6,'Bug Log'!$G$5:$G$200,E$5) | F6: =SUM(B6:E6) | G6: =COUNTIFS('Bug Log'!$B$5:$B$200,$A6,'Bug Log'!$K$5:$K$200,"Fixed")+COUNTIFS('Bug Log'!$B$5:$B$200,$A6,'Bug Log'!$K$5:$K$200,"Verified") | H6: =F6-G6
A7: D4-2 | B7: =COUNTIFS('Bug Log'!$B$5:$B$200,$A7,'Bug Log'!$G$5:$G$200,B$5) | C7: =COUNTIFS('Bug Log'!$B$5:$B$200,$A7,'Bug Log'!$G$5:$G$200,C$5) | D7: =COUNTIFS('Bug Log'!$B$5:$B$200,$A7,'Bug Log'!$G$5:$G$200,D$5) | E7: =COUNTIFS('Bug Log'!$B$5:$B$200,$A7,'Bug Log'!$G$5:$G$200,E$5) | F7: =SUM(B7:E7) | G7: =COUNTIFS('Bug Log'!$B$5:$B$200,$A7,'Bug Log'!$K$5:$K$200,"Fixed")+COUNTIFS('Bug Log'!$B$5:$B$200,$A7,'Bug Log'!$K$5:$K$200,"Verified") | H7: =F7-G7
A8: D4-3 | B8: =COUNTIFS('Bug Log'!$B$5:$B$200,$A8,'Bug Log'!$G$5:$G$200,B$5) | C8: =COUNTIFS('Bug Log'!$B$5:$B$200,$A8,'Bug Log'!$G$5:$G$200,C$5) | D8: =COUNTIFS('Bug Log'!$B$5:$B$200,$A8,'Bug Log'!$G$5:$G$200,D$5) | E8: =COUNTIFS('Bug Log'!$B$5:$B$200,$A8,'Bug Log'!$G$5:$G$200,E$5) | F8: =SUM(B8:E8) | G8: =COUNTIFS('Bug Log'!$B$5:$B$200,$A8,'Bug Log'!$K$5:$K$200,"Fixed")+COUNTIFS('Bug Log'!$B$5:$B$200,$A8,'Bug Log'!$K$5:$K$200,"Verified") | H8: =F8-G8
A9: D4-4 | B9: =COUNTIFS('Bug Log'!$B$5:$B$200,$A9,'Bug Log'!$G$5:$G$200,B$5) | C9: =COUNTIFS('Bug Log'!$B$5:$B$200,$A9,'Bug Log'!$G$5:$G$200,C$5) | D9: =COUNTIFS('Bug Log'!$B$5:$B$200,$A9,'Bug Log'!$G$5:$G$200,D$5) | E9: =COUNTIFS('Bug Log'!$B$5:$B$200,$A9,'Bug Log'!$G$5:$G$200,E$5) | F9: =SUM(B9:E9) | G9: =COUNTIFS('Bug Log'!$B$5:$B$200,$A9,'Bug Log'!$K$5:$K$200,"Fixed")+COUNTIFS('Bug Log'!$B$5:$B$200,$A9,'Bug Log'!$K$5:$K$200,"Verified") | H9: =F9-G9
A11: 2. แยกตามประเภทการส่ง
A12: ประเภท | B12: จำนวน bug | C12: สัดส่วน
A13: UAT | B13: =COUNTIF('Bug Log'!$C$5:$C$200,$A13) | C13: =IFERROR(B13/$B$16,0)
A14: Training | B14: =COUNTIF('Bug Log'!$C$5:$C$200,$A14) | C14: =IFERROR(B14/$B$16,0)
A15: Production | B15: =COUNTIF('Bug Log'!$C$5:$C$200,$A15) | C15: =IFERROR(B15/$B$16,0)
A16: รวม | B16: =SUM(B13:B15) | C16: =IFERROR(SUM(C13:C15),0)
A18: 3. สาเหตุที่ bug หลุด (จุดที่ควรปรับปรุง)
A19: หมวดสาเหตุ | B19: จำนวน bug | C19: สัดส่วน
A20: Requirement / AC ไม่ครอบคลุม | B20: =COUNTIF('Bug Log'!$H$5:$H$200,$A20) | C20: =IFERROR(B20/$B$25,0)
A21: ข้อมูลทดสอบไม่ครบ | B21: =COUNTIF('Bug Log'!$H$5:$H$200,$A21) | C21: =IFERROR(B21/$B$25,0)
A22: เทสเคสไม่ครอบคลุม | B22: =COUNTIF('Bug Log'!$H$5:$H$200,$A22) | C22: =IFERROR(B22/$B$25,0)
A23: เวลาทดสอบไม่เพียงพอ | B23: =COUNTIF('Bug Log'!$H$5:$H$200,$A23) | C23: =IFERROR(B23/$B$25,0)
A24: อื่นๆ / ยังไม่ระบุ | B24: =$B$25-SUM(B20:B23) | C24: =IFERROR(B24/$B$25,0)
A25: รวม | B25: =COUNTA('Bug Log'!$A$5:$A$200) | C25: =IFERROR(SUM(C20:C24),0)
